Workbook

Sheet Guidelines
A1: Tab Name | B1: Description | C1: Starting number of papers | D1: Final number of papers | E1: Inclusion Criteria Applied | H1: Exculsion Criteria applied
A2: Overall Dataset | B2: Set of paper retrieved from the digital libraries. It represents the dataset used for primary screening. | C2: 5147 | D2: =COUNTA('Overall Dataset'!E:E)-1 -> 3146 | E2: ID | F2: Description | G2: RQ | H2: ID | I2: Description
E3: IC1 | F3: Paper is published between 2015 and 2025 | H3: EC1 | I3: Paper is a graduate thesis or project report
E4: IC2 | F4: Paper is either a Conference or Journal paper | H4: EC2 | I4: Paper has not been peer-reviewed
E5: IC3 | F5: Paper is not a duplicate across multiple sources
A6: Preliminary Screening | B6: Checking the title and abstract of each included paper over 5 rounds considering the keywords as per EC3. Round 1: Manually done by Eoan Round 2 - 5: Automated in python A paper is included if at least one round opted to include the paper | C6: =D2 -> 3146 | D6: 215 | E6: IC4 | F6: Paper is written in English based on title and abstract | H6: EC3 | I6: Paper does not mention (cloud application or micro) and (energy or sustainability or green) in the title or abstract
A7: Primary Screening | B7: Reading the title and abstract of each included paper over three rounds. Round 1: Manually done by Eoan Round 2: Done by a LLM (GPT-4o-mini) Round 3: Done by a LLM (GTP-4o-mini) A paper is included if at least one round opted to include the paper | C7: 215 | D7: 117 | E7: IC5 | F7: Title/abstract indicates energy efficiency/consumption is considered in software engineering or architecture. | H7: EC4 | I7: Only discusses energy at hardware/infrastructure level, not software/architecture.
E8: IC6 | F8: Title/abstract refers to solutions for energy-efficient microservices. | H8: EC5 | I8: No mention of measurement, analysis, or evaluation of energy in microservices.
H9: EC6 | I9: The paper is a secondary study (SLR, mapping studies...)
A10: Secondary Screening | B10: Reading the introduction and conclusion of each included paper | C10: =D7 -> 117 | D10: =SUMIF('Secondary Screening Dataset'!A:A, "1") -> 55 | E10: IC7 | F10: The introduction/conclusion talks about how to engineer green MS | G10: RQ1 | H10: EC4 | I10: The introduction/conclusion only discusses energy at hardware/infrastructure level, not software/architecture.
E11: IC8 | F11: The introduction/conclusion discusses how they measure energy consumption in MS | G11: RQ2 | H11: EC5 | I11: The introduction/conclusion does not mention measurement, analysis, or evaluation of energy in microservices.
E12: IC9 | F12: Introduction/conclusion refers to solutions for energy-efficient microservices. | G12: RQ3 | H12: EC7 | I12: The full text of the paper is not accessible
A13: Final Screening | B13: Reading the full text of each paper | C13: =D10 -> 55 | D13: 37 | E13: P1 | F13: The text indicates that EE is considered across one or more software lifecycle stages in MS based systems. | G13: RQ1.1
E14: P2 | F14: The text refers to EC related to specific MS architectural elements (e.g. services, containers, gateways). | G14: RQ1.2
E15: P3 | F15: The text indicates methods to measure or assess EC in MS systems. | G15: RQ2.1
E16: P4 | F16: The text mentions the use or development of specific tools for analyzing or monitoring energy in MS. | G16: RQ2.2
E17: P5 | F17: The text refers to the use or development of metrics for evaluating energy efficiency in MS systems. | G17: RQ2.3
E18: P6 | F18: The text presents or summarizes architectural approaches or solutions aimed at improving EE in MS. | G18: RQ3.1
E19: P7 | F19: The text mentions trade-offs between EE and other system qualities (e.g., performance, scalability). | G19: RQ3.2
E20: P8 | F20: The text discusses challenges or barriers to implementing EE in MS. | G20: RQ3.3
A21: Final Set of Papers | C21: 37
A22: List of Parameters | B22: The tab reports the list of parameters with description. In addition, the list of possible values for parameters are listed and described. | D22: None | F22: None

Sheet Snowball Process
A1: Step # | B1: Tab Name | C1: Description | D1: Starting number of papers | E1: Final number of papers | F1: Inclusion Criteria Applied | I1: Exculsion Criteria applied | M1: Snowball Repeats
A2: 1 | B2: Overall Dataset | C2: Set of paper retrieved from the digital libraries. It represents the dataset used for primary screening. | D2: Forward: 1001 Backward: 1503 Total: 2504 | E2: 403 | F2: ID | G2: Description | H2: RQ | I2: ID | J2: Description | M2: Checks to make (Snowball)
F3: IC1 | G3: Paper is published between 2015 and 2025 | I3: EC1 | J3: Paper is a graduate thesis or project report | M3: - Check against first dataset (3146) - Only English - Peer reviewed - Remove duplicates - Between 2015 - 2025
F4: IC2 | G4: Paper is either a Conference or Journal paper | I4: EC2 | J4: Paper has not been peer-reviewed
F5: IC3 | G5: Paper is not a duplicate across multiple sources | I5: EC3 | J5: The paper was in the original dataset
B6: Preliminary Screening | C6: Checking the title and abstract of each included paper over 2 rounds considering the keywords as per EC3. Round 1 - 2: Automated in python A paper is included if at least one round opted to include the paper | D6: =E2 -> 403 | E6: 25 | F6: IC4 | G6: Paper is written in English based on title and abstract | I6: EC3 | J6: Paper does not mention (cloud application or micro) and (energy or sustainability or green) in the title or abstract | M6: Asreview settings - Do one randomly - Do one 80/20
B7: Primary Screening | C7: Reading the title and abstract of each included paper over three rounds. Round 1: Manually done by Eoan Round 2: Done by a LLM (GPT-4o-mini) Round 3: Done by a LLM (GTP-4o-mini) A paper is included if at least one round opted to include the paper | D7: =E6 -> 25 | E7: 12 | F7: IC5 | G7: Title/abstract indicates energy efficiency/consumption is considered in software engineering or architecture. | I7: EC4 | J7: Only discusses energy at hardware/infrastructure level, not software/architecture.
F8: IC6 | G8: Title/abstract refers to solutions for energy-efficient microservices. | I8: EC5 | J8: No mention of measurement, analysis, or evaluation of energy in microservices.
I9: EC6 | J9: The paper is a secondary study (SLR, mapping studies...)
B10: Secondary Screening | C10: Reading the introduction and conclusion of each included paper | D10: 12 | E10: 9 | F10: IC7 | G10: The introduction/conclusion talks about how to engineer green MS | H10: RQ1 | I10: EC7 | J10: The introduction/conclusion only discusses energy at hardware/infrastructure level, not software/architecture. | M10: Read introduction/conclusion
F11: IC8 | G11: The introduction/conclusion discusses how they measure energy consumption in MS | H11: RQ2 | I11: EC8 | J11: The introduction/conclusion does not mention measurement, analysis, or evaluation of energy in microservices.
F12: IC9 | G12: Introduction/conclusion refers to solutions for energy-efficient microservices. | H12: RQ3 | I12: EC9 | J12: The full text of the paper is not accessible
B13: Final Screening | D13: 9 | E13: 3 | F13: P1 | G13: The text indicates that EE is considered across one or more software lifecycle stages in MS based systems. | H13: RQ1.1
F14: P2 | G14: The text refers to EC related to specific MS architectural elements (e.g. services, containers, gateways). | H14: RQ1.2
F15: P3 | G15: The text indicates methods to measure or assess EC in MS systems. | H15: RQ2.1
F16: P4 | G16: The text mentions the use or development of specific tools for analyzing or monitoring energy in MS. | H16: RQ2.2
F17: P5 | G17: The text refers to the use or development of metrics for evaluating energy efficiency in MS systems. | H17: RQ2.3
F18: P6 | G18: The text presents or summarizes architectural approaches or solutions aimed at improving EE in MS. | H18: RQ3.1
F19: P7 | G19: The text mentions trade-offs between EE and other system qualities (e.g., performance, scalability). | H19: RQ3.2
F20: P8 | G20: The text discusses challenges or barriers to implementing EE in MS. | H20: RQ3.3
B21: Final Set of Papers
B22: List of Parameters | C22: The tab reports the list of parameters with description. In addition, the list of possible values for parameters are listed and described. | E22: None | G22: None

Sheet Parameters
A1: PARAMETER ID | B1: Parameter Name | C1: Type | D1: Example Values | E1: Description
A2: RQ1: Where is energy efficiency considered in microservice architecture research?
A3: RQ1.1: At which stages of the software lifecycle is energy efficiency considered in microservices?
A4: RQ1.1.P1 | B4: Energy Consideration Stage | C4: Single | D4: Requirements, Design, Implementation, Testing, Deployment, Operations | E4: At what point in the lifecycle energy efficiency becomes a stated concern or point of attention | H4: =IFERROR(__xludf.DUMMYFUNCTION("CONCAT(A4,CONCAT(""_"", REGEXREPLACE(B4, "" "", """")))"),"RQ1.1.P1_EnergyConsiderationStage") -> RQ1.1.P1_EnergyConsiderationStage
A5: RQ1.1.P2 | B5: Energy Intervention Stage | C5: Single | D5: Explicit requirements, Implicit concerns, Post-deployment optimization | E5: At what point in the lifecycle energy efficiency concerns are addressed | H5: =IFERROR(__xludf.DUMMYFUNCTION("CONCAT(A5,CONCAT(""_"", REGEXREPLACE(B5, "" "", """")))"),"RQ1.1.P2_EnergyInterventionStage") -> RQ1.1.P2_EnergyInterventionStage
A6: RQ1.1.P3 | B6: Energy Optimisation Technique | C6: Single | D6: Build-in, Add-on, External monitoring, Manual assessment | E6: How energy efficiency is introduced into the system or process | H6: =IFERROR(__xludf.DUMMYFUNCTION("CONCAT(A6,CONCAT(""_"", REGEXREPLACE(B6, "" "", """")))"),"RQ1.1.P3_EnergyOptimisationTechnique") -> RQ1.1.P3_EnergyOptimisationTechnique
A7: RQ1.2: Which microservice architectural elements are primarily considered when measuring energy consumption?
A8: RQ1.2.P1 | B8: Component Type | C8: Single | D8: Service units, API Gateways, Message brokers, Databases, Load balancers, Containers | E8: Captures the architectural element to which energy consumption is measured or attributed. | H8: =IFERROR(__xludf.DUMMYFUNCTION("CONCAT(A8,CONCAT(""_"", REGEXREPLACE(B8, "" "", """")))"),"RQ1.2.P1_ComponentType") -> RQ1.2.P1_ComponentType
A9: RQ1.2.P2 | B9: Energy consumption source | C9: Multiple | D9: Processing overhead, Communication overhead, State management, Resource allocation, Idle consumption | E9: The type of system activity responsible for the measured energy consumption. | H9: =IFERROR(__xludf.DUMMYFUNCTION("CONCAT(A9,CONCAT(""_"", REGEXREPLACE(B9, "" "", """")))"),"RQ1.2.P2_Energyconsumptionsource") -> RQ1.2.P2_Energyconsumptionsource
A10: RQ1.2.P3 | B10: Component Relationship | C10: Single | D10: Isolated, Interconnected, Cascading effect, System-wide impact | E10: Describes how interactions and dependencies between components are characterised when reasoning about energy efficiency | H10: =IFERROR(__xludf.DUMMYFUNCTION("CONCAT(A10,CONCAT(""_"", REGEXREPLACE(B10, "" "", """")))"),"RQ1.2.P3_ComponentRelationship") -> RQ1.2.P3_ComponentRelationship
A11: RQ2: How is energy consumption measured in microservices?
A12: RQ2.1: What methods are used to measure energy consumption in microservices?
A13: RQ2.1.P1 | B13: Measurement Level | C13: Single | D13: Hardware, OS, Container, Application, Cross-cutting | E13: Represents at which level energy consumption is measured | H13: =IFERROR(__xludf.DUMMYFUNCTION("CONCAT(A13,CONCAT(""_"", REGEXREPLACE(B13, "" "", """")))"),"RQ2.1.P1_MeasurementLevel") -> RQ2.1.P1_MeasurementLevel
A14: RQ2.1.P2 | B14: Measurement Technique | C14: Single | D14: Static analysis, Dynamic profiling, Model-based estimation, Hybrid | E14: Describes the technique used to measure energy consumption | H14: =IFERROR(__xludf.DUMMYFUNCTION("CONCAT(A14,CONCAT(""_"", REGEXREPLACE(B14, "" "", """")))"),"RQ2.1.P2_MeasurementTechnique") -> RQ2.1.P2_MeasurementTechnique
A15: RQ2.1.P3 | B15: Data Collection | C15: Single | D15: Sampling, Continuous monitoring, Event-triggered, Benchmark testing | E15: Refers to the method of collecting energy consumption data | H15: =IFERROR(__xludf.DUMMYFUNCTION("CONCAT(A15,CONCAT(""_"", REGEXREPLACE(B15, "" "", """")))"),"RQ2.1.P3_DataCollection") -> RQ2.1.P3_DataCollection
A16: RQ2.1.P4 | B16: Implementation Approach | C16: Single | D16: Source code instrumentation, Binary instrumentation, External monitoring | E16: Indicates the approach used to implement the measurement | H16: =IFERROR(__xludf.DUMMYFUNCTION("CONCAT(A16,CONCAT(""_"", REGEXREPLACE(B16, "" "", """")))"),"RQ2.1.P4_ImplementationApproach") -> RQ2.1.P4_ImplementationApproach
A17: RQ2.2: How are tools used for energy consumption analysis in microservices?
A18: RQ2.2.P1 | B18: Tool Type | C18: Single | D18: Commercial, Open source, Research prototype, Custom in-house | E18: Categorizes the type of tools used for energy consumption analysis | H18: =IFERROR(__xludf.DUMMYFUNCTION("CONCAT(A18,CONCAT(""_"", REGEXREPLACE(B18, "" "", """")))"),"RQ2.2.P1_ToolType") -> RQ2.2.P1_ToolType
A19: RQ2.2.P2 | B19: Deployment Method | C19: Single | D19: Agent-based, Sidecar, External, Embedded | E19: Describes how the tool is deployed within the system | H19: =IFERROR(__xludf.DUMMYFUNCTION("CONCAT(A19,CONCAT(""_"", REGEXREPLACE(B19, "" "", """")))"),"RQ2.2.P2_DeploymentMethod") -> RQ2.2.P2_DeploymentMethod
A20: RQ2.2.P3 | B20: Analysis Capability | C20: Single | D20: Real-time, Historical, Predictive, Comparative | E20: Defines the type of analysis the tool provides | H20: =IFERROR(__xludf.DUMMYFUNCTION("CONCAT(A20,CONCAT(""_"", REGEXREPLACE(B20, "" "", """")))"),"RQ2.2.P3_AnalysisCapability") -> RQ2.2.P3_AnalysisCapability
A21: RQ2.2.P4 | B21: Granularity | C21: Single | D21: System-wide, Service-specific, Transaction-level, Code-block level | E21: Indicates the level of detail at which the tool analyzes energy consumption | H21: =IFERROR(__xludf.DUMMYFUNCTION("CONCAT(A21,CONCAT(""_"", REGEXREPLACE(B21, "" "", """")))"),"RQ2.2.P4_Granularity") -> RQ2.2.P4_Granularity
A22: RQ2.3: What energy efficiency metrics are commonly used to evaluate microservices?
A23: RQ2.3.P1 | B23: Metric Type | C23: Single | D23: Absolute (Joules, Watts), Relative (efficiency ratio), Composite | E23: The type of metric used to evaluate energy efficiency | H23: =IFERROR(__xludf.DUMMYFUNCTION("CONCAT(A23,CONCAT(""_"", REGEXREPLACE(B23, "" "", """")))"),"RQ2.3.P1_MetricType") -> RQ2.3.P1_MetricType
A24: RQ2.3.P2 | B24: Measurement Scope | C24: Multiple | D24: CPU, Memory, Network, Storage, Full-stack | E24: The speicif system resource or scope being measureed for energy consumption | H24: =IFERROR(__xludf.DUMMYFUNCTION("CONCAT(A24,CONCAT(""_"", REGEXREPLACE(B24, "" "", """")))"),"RQ2.3.P2_MeasurementScope") -> RQ2.3.P2_MeasurementScope
A25: RQ2.3.P3 | B25: Normalization Basis | C25: Multiple | D25: Per request, Per transaction, Per user, Per service | E25: Defines how energy consumption is normalized to provide meaningful comparisons | H25: =IFERROR(__xludf.DUMMYFUNCTION("CONCAT(A25,CONCAT(""_"", REGEXREPLACE(B25, "" "", """")))"),"RQ2.3.P3_NormalizationBasis") -> RQ2.3.P3_NormalizationBasis
A26: RQ2.3.P4 | B26: Business Relevance | C26: Multiple | D26: Cost-focused, Performance-balanced, Carbon footprint | E26: Represents the business-oriented perspective of the metric | H26: =IFERROR(__xludf.DUMMYFUNCTION("CONCAT(A26,CONCAT(""_"", REGEXREPLACE(B26, "" "", """")))"),"RQ2.3.P4_BusinessRelevance") -> RQ2.3.P4_BusinessRelevance
A27: RQ3: What architectural solutions exist for energy-efficient microservices?
A28: RQ3.1: What approaches are used to improve energy efficiency in microservice architectures?
A29: RQ3.1.P1 | B29: Energy Management Strategy | C29: Single | D29: Strangler pattern, Incremental refactoring, Complete rebuild, Containerization | E29: How existing systems are updated for energy efficiency | H29: =IFERROR(__xludf.DUMMYFUNCTION("CONCAT(A29,CONCAT(""_"", REGEXREPLACE(B29, "" "", """")))"),"RQ3.1.P1_EnergyManagementStrategy") -> RQ3.1.P1_EnergyManagementStrategy
A30: RQ3.1.P2 | B30: Tactic Category | C30: Single | D30: Architectural patterns, Design patterns, Resource management tactics, Request handling tactics, Data management tactics | E30: Types of patterns and tactics used to improve energy efficiency | H30: =IFERROR(__xludf.DUMMYFUNCTION("CONCAT(A30,CONCAT(""_"", REGEXREPLACE(B30, "" "", """")))"),"RQ3.1.P2_TacticCategory") -> RQ3.1.P2_TacticCategory
A31: RQ3.1.P3 | B31: Implementation Technologies | C31: Single | D31: Containerization, Serverless, Service mesh, Orchestration platforms, Green computing frameworks | E31: Specific technologies enabling energy-efficient solutions | H31: =IFERROR(__xludf.DUMMYFUNCTION("CONCAT(A31,CONCAT(""_"", REGEXREPLACE(B31, "" "", """")))"),"RQ3.1.P3_ImplementationTechnologies") -> RQ3.1.P3_ImplementationTechnologies
A32: RQ3.2: What trade-offs exist between energy efficiency and other quality attributes in microservice architectures?
A33: RQ3.2.P1 | B33: Quality Attribute | C33: Multiple | D33: Performance, Scalability, Maintainability, Reliability, Security, Availability | E33: System qualities impacted by energy efficiency efforts | H33: =IFERROR(__xludf.DUMMYFUNCTION("CONCAT(A33,CONCAT(""_"", REGEXREPLACE(B33, "" "", """")))"),"RQ3.2.P1_QualityAttribute") -> RQ3.2.P1_QualityAttribute
A34: RQ3.2.P2 | B34: Trade-off Relationship | C34: Single | D34: Competing, Complementary, Context-dependent, Independent | E34: Nature of the interaction between energy efficiency and other qualities | H34: =IFERROR(__xludf.DUMMYFUNCTION("CONCAT(A34,CONCAT(""_"", REGEXREPLACE(B34, "" "", """")))"),"RQ3.2.P2_Trade-offRelationship") -> RQ3.2.P2_Trade-offRelationship
A35: RQ3.2.P3 | B35: Trade-off Strategy | C35: Single | D35: Architectural refactoring, Compensating tactics, Prioritization frameworks, Incremental evolution | E35: Methods to manage or mitigate trade-offs | H35: =IFERROR(__xludf.DUMMYFUNCTION("CONCAT(A35,CONCAT(""_"", REGEXREPLACE(B35, "" "", """")))"),"RQ3.2.P3_Trade-offStrategy") -> RQ3.2.P3_Trade-offStrategy
A36: RQ3.3: What challenges affect the adoption of energy-efficient architectural solutions in microservices?
A37: RQ3.3.P1 | B37: Challenge Type | C37: Single | D37: Technical, Organizational, Knowledge-based, Economic | E37: Type of challenges to adoptation | H37: =IFERROR(__xludf.DUMMYFUNCTION("CONCAT(A37,CONCAT(""_"", REGEXREPLACE(B37, "" "", """")))"),"RQ3.3.P1_ChallengeType") -> RQ3.3.P1_ChallengeType
A38: RQ3.3.P2 | B38: Adoption Phase | C38: Single | D38: Design-time, Implementation, Deployment, Runtime | E38: Lifecycle phase where challenges occur | H38: =IFERROR(__xludf.DUMMYFUNCTION("CONCAT(A38,CONCAT(""_"", REGEXREPLACE(B38, "" "", """")))"),"RQ3.3.P2_AdoptionPhase") -> RQ3.3.P2_AdoptionPhase
A39: RQ3.3.P3 | B39: Challenge Complexity | C39: Single | E39: Difficulty level of the challenge | H39: =IFERROR(__xludf.DUMMYFUNCTION("CONCAT(A39,CONCAT(""_"", REGEXREPLACE(B39, "" "", """")))"),"RQ3.3.P3_ChallengeComplexity") -> RQ3.3.P3_ChallengeComplexity
A40: RQ3.3.P4 | B40: Mitigation Approach | C40: Single | D40: Tooling improvements, Knowledge sharing, Incremental adoption, Organizational change | E40: Strategies to address challenges | H40: =IFERROR(__xludf.DUMMYFUNCTION("CONCAT(A40,CONCAT(""_"", REGEXREPLACE(B40, "" "", """")))"),"RQ3.3.P4_MitigationApproach") -> RQ3.3.P4_MitigationApproach

Sheet Search Strings
A1: Iteration | B1: Search String | C1: Type | D1: Results
A2: 5 | B2: ("microservice" OR "micro-service" OR "microservices" OR "micro-services") AND ("energy consumption" OR "power consumption" OR "energy efficiency") AND ("measurement" OR "measurements" OR "profiling" OR "monitoring") AND ("tradeoff" OR "trade-off" OR "quality" OR "qualities") AND ("pattern" OR "patterns" OR "tactic" OR "tactics") | C2: General
B3: ("microservice" OR "micro-service" OR "microservices" OR "micro-services") AND ("energy consumption" OR "power consumption" OR "energy efficiency") AND ("measurement" OR "measurements" OR "profiling" OR "monitoring") AND ("tradeoff" OR "trade-off" OR "quality" OR "qualities") AND ("pattern" OR "patterns" OR "tactic" OR "tactics") AND PUBYEAR > 2014 AND PUBYEAR < 2026 | C3: Scopus
B4: (("Full Text Only":"microservice*") OR ("Full Text Only":"micro-service*")) AND (("Full Text Only":"energy consumption") OR ("Full Text Only":"power consumption") OR ("Full Text Only":"energy efficiency")) AND (("Full Text Only":"measurement*") OR ("Full Text Only":"profiling") OR ("Full Text Only":"monitoring")) AND (("Full Text Only":"trade*off*") OR ("Full Text Only":"qualit*")) AND (("Full Text Only":"pattern*") OR ("Full Text Only":"tactic*")) | C4: IEEE
D5: Database | E5: Total Results | F5: Conference + Journal Papers
D6: ACM | E6: 564 | F6: 554
D7: ACM Expanded | E7: 1052 | F7: 589
D8: IEEE | E8: 1285 | F8: 1041
D9: Scopus | E9: 307 | F9: 215
D10: Springer | E10: 622 | F10: 407
A12: 6 (Selected) | B12: ("microservice" OR "micro-service" OR "microservices" OR "micro-services") AND ("energy consumption" OR "power consumption" OR "energy efficiency") AND ("measurement" OR "measurements" OR "profiling" OR "monitoring") AND ("tradeoff" OR "trade-off" OR "quality" OR "qualities" OR "pattern" OR "patterns" OR "tactic" OR "tactics") | C12: General
B13: ("microservice" OR "micro-service" OR "microservices" OR "micro-services") AND ("energy consumption" OR "power consumption" OR "energy efficiency") AND ("measurement" OR "measurements" OR "profiling" OR "monitoring") AND ("tradeoff" OR "trade-off" OR "quality" OR "qualities" OR "pattern" OR "patterns" OR "tactic" OR "tactics") AND PUBYEAR > 2014 AND PUBYEAR < 2026 | C13: Scopus
B14: (("Full Text Only":"microservice*") OR ("Full Text Only":"micro-service*")) AND (("Full Text Only":"energy consumption") OR ("Full Text Only":"power consumption") OR ("Full Text Only":"energy efficiency")) AND (("Full Text Only":"measurement*") OR ("Full Text Only":"profiling") OR ("Full Text Only":"monitoring")) AND (("Full Text Only":"trade*off*") OR ("Full Text Only":"qualit*") OR ("Full Text Only":"pattern*") OR ("Full Text Only":"tactic*")) | C14: IEEE
D15: Database | E15: Total Results | F15: Conference + Journal Papers
D16: ACM | E16: 739 | F16: 720 | G16: 720
D17: ACM Expanded | E17: 1495 | F17: 806 (658 | G17: 806
D18: IEEE | E18: 2459 | F18: 2107 (1414 conference) | G18: 2107
D19: Scopus | E19: 1031 | F19: 804 | G19: 804
D20: Springer | E20: 1020 | F20: 710 | G20: 710

Sheet ASReview Results Overview
A1: Round # | B1: Date | C1: # Relevant | D1: # Labeled | E1: Notes
A2: Round 1 | B2: 45748 | C2: 142 | D2: 1664 | E2: Maximum
A3: Round 2 | B3: 45798 | C3: 156 | D3: 2291 | E3: 5% randomness
A4: Round 3 | B4: 45798 | C4: 199 | D4: 3146 | E4: 5% randomness
A5: Round 4 | B5: 45798 | C5: 190 | D5: 2102 | E5: 0 randomness
A6: Round 5 | B6: 45798 | C6: 193 | D6: 2292 | E6: 0 randomness
A9: Round # | B9: Date | C9: # Relevant | D9: # Labeled | E9: Notes
A10: Round 1 | B10: 45957 | C10: 25 | D10: 403 | E10: Maximum
A11: Round 2 | B11: 45957 | C11: 25 | D11: 403 | E11: 5% randomness

Sheet Overall Dataset
A1: Key | B1: Item Type | C1: Publication Year | D1: Author | E1: Title | F1: Publication Title | G1: ISBN | H1: ISSN | I1: DOI | J1: Url | K1: Date | L1: Date Added | M1: Date Modified | N1: Access Date | O1: Pages | P1: Num Pages | Q1: Issue | R1: Volume | S1: Number Of Volumes | T1: Journal Abbreviation | U1: Short Title | V1: Series | W1: Series Number | X1: Series Text | Y1: Series Title | Z1: Publisher | AA1: Place | AB1: Language | AC1: Rights | AD1: Type | AE1: Archive | AF1: Archive Location | AG1: Library Catalog | AH1: Call Number | AI1: Extra | AJ1: Notes | AK1: File Attachments | AL1: Link Attachments | AM1: Automatic Tags | AN1: Editor | AO1: Series Editor | AP1: Translator | AQ1: Contributor | AR1: Attorney Agent | AS1: Book Author | AT1: Cast Member | AU1: Commenter | AV1: Composer | AW1: Cosponsor | AX1: Counsel | AY1: Interviewer | AZ1: Producer | BA1: Recipient | BB1: Reviewed Author | BC1: Scriptwriter | BD1: Words By | BE1: Guest | BF1: Number | BG1: Edition | BH1: Running Time | BI1: Scale | BJ1: Medium | BK1: Artwork Size | BL1: Filing Date | BM1: Application Number | BN1: Assignee | BO1: Issuing Authority | BP1: Country | BQ1: Meeting Name | BR1: Conference Name | BS1: Court | BT1: References | BU1: Reporter | BV1: Legal Status | BW1: Priority Numbers | BX1: Programming Language | BY1: Version | BZ1: System | CA1: Code | CB1: Code Number | CC1: Section | CD1: Session | CE1: Committee | CF1: History | CG1: Legislative Body | CH1: Author Affiliations | CI1: Date Added To Xplore | CJ1: Start Page | CK1: End Page | CL1: Abstract | CM1: ISBNs | CN1: Funding Information | CO1: PDF Link | CP1: Author Keywords | CQ1: Mesh_Terms | CR1: Article Citation Count | CS1: Patent Citation Count | CT1: Reference Count | CU1: License | CV1: Issue Date | CW1: Meeting Date | CX1: Author full names | CY1: Author(s) ID | CZ1: Year | DA1: Source title | DB1: Art. No. | DC1: Page start | DD1: Page end | DE1: Page count | DF1: Cited by | DG1: Link | DH1: Publication Stage | DI1: Open Access | DJ1: Source | DK1: EID | DL1: Keywords
A2: PPQI2ZES | B2: conferencePaper | C2: 2024 | D2: Serrano-Gutierrez, Pablo; Ayala, Inmaculada | E2: Using Energy Consumption for Self-adaptation in&nbsp;FaaS | F2: Reuse and Software Quality: 21st International Conference on Software and Systems Reuse, ICSR 2024, Limassol, Cyprus, June 19‚Äì20, 2024, Proceedings | G2: 978-3-031-66458-8 | I2: 10.1007/978-3-031-66459-5_8 | J2: https://doi.org/10.1007/978-3-031-66459-5_8 | K2: 2024 | L2: 45734.379 | M2: 45734.379 | O2: 123‚Äì134 | Z2: Springer-Verlag | AA2: Berlin, Heidelberg | AI2: event-place: Limassol, Cyprus | CL2: One of the programming models that has been developing the most in recent years is Function as a Service (FaaS). The growing concern over data centre energy footprints has driven sustainable software development. In serverless applications, energy consumption depends on the energy consumption of the application‚Äôs functions. However, measuring energy proves challenging, and the results‚Äô variability complicates optimisation efforts at runtime. This article addresses this issue by measuring serverless function energy consumption and exploring integration into an optimisation system that selects implementations based on their current energy footprint. For this, we have integrated an energy measurement software into a FaaS system. We have analysed how to properly process the data and how to use them to perform self-adaptation. We present a series of methods and policies that make our system not only capable of detecting variations in the energy consumption of the functions, but it does so taking into account the variability in the measurements that each function may present. Our experiments showcase proper integration in a self-adaptive system, showing a reduction up to 5% in energy consumption due to functions in a test application. | DL2: serverless; sustainability; self-adaptive
A3: MF6HYN8W | B3: conferencePaper | C3: 2024 | D3: Galantino, Stefano; Pinto, Andrea; Esposito, Flavio; Manzalini, Antonio; Risso, Fulvio | E3: Balancing Energy Efficiency and Infrastructure Knowledge in Cloud-to-Edge Task Distribution Systems | F3: Proceedings of the 1st International Workshop on MetaOS for the Cloud-Edge-IoT Continuum | G3: 979-8-4007-0543-4 | I3: 10.1145/3642975.3678965 | J3: https://doi.org/10.1145/3642975.3678965 | K3: 2024 | L3: 45734.379 | M3: 45734.379 | O3: 28‚Äì34 | V3: MECC '24 | Z3: Association for Computing Machinery | AA3: New York, NY, USA | AI3: event-place: Athens, Greece | CL3: In the rapidly evolving landscape of distributed computing, maintaining energy efficiency in edge and data center infrastructures has become critical. While the problem has been faced with centralized approaches assuming knowledge of the available underlying infrastructure resources, this paper introduces a distributed task allocation framework emphasizing energy awareness without requiring infrastructure knowledge. The framework is designed to optimize energy consumption in heterogeneous computing environments, leveraging a distributed consensus algorithm that allows nodes to maximize individual or global goals. Each private custom utility function enables a node to carefully determine whether executing a task is efficient, thus ensuring flexibility in the task allocation process based on local preferences. While showcasing the energy efficiency of our framework, we also illustrate that it is not necessary to disclose the underlying infrastructure resources status, ensuring the preservation of potentially sensitive local resources information. Experimental results demonstrate the framework's ability to achieve optimal power consumption outcomes while maintaining privacy, offering a significant advancement over traditional centralized allocation policies and Kubernetes-like scheduling algorithms.
A4: LKFV3LAA | B4: conferencePaper | C4: 2022 | D4: M√ºller, Benedikt Tobias; Ender, Marvin; Swiadek, Jan Erik; Jin, Mengcheng; Winkel, Simon; Niedziela, Dominik; Li, Bin; H√ºntelmann, Jelle; M√ºller, Emmanuel | E4: ADEPT: Anomaly Detection, Explanation and Processing for Time Series with a Focus on Energy Consumption Data | F4: Machine Learning and Knowledge Discovery in Databases: European Conference, ECML PKDD 2022, Grenoble, France, September 19‚Äì23, 2022, Proceedings, Part VI | G4: 978-3-031-26421-4 | I4: 10.1007/978-3-031-26422-1_43 | J4: https://doi.org/10.1007/978-3-031-26422-1_43 | K4: 2022 | L4: 45734.379 | M4: 45734.379 | O4: 622‚Äì626 | Z4: Springer-Verlag | AA4: Berlin, Heidelberg | AI4: event-place: Grenoble, France | CL4: Anomaly detection techniques are applicable for recognizing excessive energy consumption and device failure, thereby contributing to the maintenance of operational and sustainable energy supply systems. In this context, human decision makers can benefit from receiving explanation attempts for detected anomalies as part of a semi-automated software solution. Therefore we introduce the framework ADEPT, which comprises interfaces for processing user-supplied time series data and interactively visualizing explanatory anomaly information. Our framework features several shallow and deep machine learning algorithms for anomaly detection and explanation. We demonstrate ADEPT using energy consumption data collected from our university campus. | DL4: Anomaly detection; Energy consumption; Explainability
A5: ZIKASWQT | B5: conferencePaper | C5: 2023 | D5: Sim√µes, Bruno; Del Puy Carretero, Mar√≠a; Martinez Santiago, Jorge; Mu√±oz Segovia, Sebastian; Alcain, Nieves | E5: TwinArk: A Unified Framework for Digital Twins based on Micro-frontends, Micro-Services, and Web 3D | F5: Proceedings of the 28th International ACM Conference on 3D Web Technology | G5: 979-8-4007-0324-9 | I5: 10.1145/3611314.3615915 | J5: https://doi.org/10.1145/3611314.3615915 | K5: 2023 | L5: 45734.379 | M5: 45734.379 | V5: Web3D '23 | Z5: Association for Computing Machinery | AA5: New York, NY, USA | AI5: event-place: San Sebastian, Spain | CL5: The introduction of the Digital Twin (DT) has sparked a great deal of interest in the virtual replication of physical assets and processes. However, to fully realize the potential of DT, companies require robust and scalable front-end solutions. This study proposes harnessing micro-frontend technologies to surmount the limitations of monolithic front-end frameworks, thereby crafting effective presentation layers tailored for industrial companies. By decomposing complex and distributed systems into modular web-based DT, the proposed framework enables better scalability, synergy, and efficient application development. It also tackles the intricacies introduced by complex multi-vendor elements within DT and the orchestration of services and virtual environments. Research is focused on developing an architecture that facilitates seamless connectivity between multiple blocks of DT as well as interactivity and immersive experiences. Our study offers insights into our journey of implementing this framework for various industrial use cases, such as training, monitoring, and control, highlighting the benefits, drawbacks, and challenges. Ultimately, this research aims to accelerate the creation of DT, improve maintainability, and increase efficiency and productivity in industrial environments. | DL5: digital twins; GUI; Web3D
A6: 87Y8HT3V | B6: conferencePaper | C6: 2019 | D6: Duarte, Lucio Mauro; da Silva Alves, Danilo; Toresan, Bruno Ramos; Maia, Paulo Henrique; Silva, Davi | E6: A Model-based Framework for the Analysis of Software Energy Consumption | F6: Proceedings of the XXXIII Brazilian Symposium on Software Engineering | G6: 978-1-4503-7651-8 | I6: 10.1145/3350768.3353813 | J6: https://doi.org/10.1145/3350768.3353813 | K6: 2019 | L6: 45734.379 | M6: 45734.379 | O6: 67‚Äì72 | V6: SBES '19 | Z6: Association for Computing Machinery | AA6: New York, NY, USA | AI6: event-place: Salvador, Brazil | CL6: Software is present in all types of devices, some of them with restrictions as to the amount of energy they can spend to execute software applications. For this reason, energy costs are becoming an important factor during software development and evolution. However, there is still little support for creating energy-efficient software. In this work, we introduce a possible framework for software energy costs evaluation based on model analysis. We model software as Labelled Transitions Systems (LTS) and annotate these models with energy costs, which can be obtained using existing tools. We can then apply graph-based algorithms to traverse the models to obtain information about energy consumption related to software behaviour, such as its most/least costly execution, the cost of a specific execution, and the average cost of executing the software. No existing tool currently provides all the necessary analyses, even though they are essential for energy-consumption evaluation. We have conducted a small experiment with our framework where we employed jRAPL to measure energy costs. We annotated the models with the collected energy costs using an extended version of the LoTuS tool, where we have also implemented some of the desired analyses. Based on this support and on our initial results, we believe developers could create software more energy-efficient and consider possible trade-offs related to time, space, and energy costs when producing new versions of their systems. | DL6: Embedded Software; Energy Consumption Evaluation; Labelled Transition System; Model-based Analysis
A7: HPFCIEF2 | B7: conferencePaper | C7: 2019 | D7: Lin, Pingrong; Lin, Zheyuan; Shi, Xiaoquan | E7: Research on Optimization of Course Selection System Based on Micro service and Dynamic Resource Extension | F7: Proceedings of the 4th International Conference on Big Data and Computing | G7: 978-1-4503-6278-8 | I7: 10.1145/3335484.3335546 | J7: https://doi.org/10.1145/3335484.3335546 | K7: 2019 | L7: 45734.379 | M7: 45734.379 | O7: 115‚Äì119 | V7: ICBDC '19 | Z7: Association for Computing Machinery | AA7: New York, NY, USA | AI7: event-place: Guangzhou, China | CL7: In view of the fact that the course selection system in Colleges and universities has short burst access, large concurrent business and complex business, and combined with the existing course selection system of South China Institute of Software Engineering of Guangzhou University, an optimization scheme based on micro service and dynamic resource extension is constructed. The scheme can solve the problem of low performance of course selection system by building a micro-service architecture, splitting the business services of course selection system, scaling up the cluster of servers, and expanding the resources dynamically. The performance comparison before and after optimization shows that the performance of the course selection system has been greatly improved, and the scheme is feasible and effective. | DL7: micro-service; course selection system; dynamic resource expansion
A8: 8YLDVF6H | B8: conferencePaper | C8: 2022 | D8: Tang, Wenda; Ke, Yutao; Fu, Senbo; Jiang, Hongliang; Wu, Junjie; Peng, Qian; Gao, Feng | E8: Demeter: QoS-aware CPU scheduling to reduce power consumption of multiple black-box workloads | F8: Proceedings of the 13th Symposium on Cloud Computing | G8: 978-1-4503-9414-7 | I8: 10.1145/3542929.3563476 | J8: https://doi.org/10.1145/3542929.3563476 | K8: 2022 | L8: 45734.379 | M8: 45734.379 | O8: 31‚Äì46 | V8: SoCC '22 | Z8: Association for Computing Machinery | AA8: New York, NY, USA | AI8: event-place: San Francisco, California | CL8: Energy consumption in cloud data centers has become an increasingly important contributor to greenhouse gas emissions and operation costs. To reduce energy-related costs and improve environmental sustainability, most modern data centers consolidate Virtual Machine (VM) workloads belonging to different application classes, some being latency-critical (LC) and others being more tolerant to performance changes, known as best-effort (BE). However, in public cloud scenarios, the real classes of applications are often opaque to data center operators. The heterogeneous applications from different cloud tenants are usually consolidated onto the same hosts to improve energy efficiency, but it is not trivial to guarantee decent performance isolation among colocated workloads. We tackle the above challenges by introducing Demeter, a QoS-aware power management controller for heterogeneous black-box workloads in public clouds. Demeter is designed to work without offline profiling or prior knowledge about black-box workloads. Through the correlation analysis between network throughput and CPU resource utilization, Demeter automatically classifies black-box workloads as either LC or BE. By provisioning differentiated CPU management strategies (including dynamic core allocation and frequency scaling) to LC and BE workloads, Demeter achieves considerable power savings together with a minimum impact on the performance of all workloads. We discuss the design and implementation of Demeter in this work, and conduct extensive experimental evaluations to reveal its effectiveness. Our results show that Demeter not only meets the performance demand of all workloads, but also responds quickly to dynamic load changes in our cloud environment. In addition, Demeter saves an average of 10.6% power consumption than state of the art mechanisms. | DL8: cloud computing; power management; quality of service; workload characterization
A9: XXKXIWC6 | B9: conferencePaper | C9: 2021 | D9: Valera, Hernan Humberto Alvarez; Dalmau, Marc; Roose, Philippe; Larracoechea, Jorge; Herzog, Christina | E9: An energy saving approach: understanding microservices as multidimensional entities in p2p networks | F9: Proceedings of the 36th Annual ACM Symposium on Applied Computing | G9: 978-1-4503-8104-8 | I9: 10.1145/3412841.3441888 | J9: https://doi.org/10.1145/3412841.3441888 | K9: 2021 | L9: 45734.379 | M9: 45734.379 | O9: 69‚Äì78 | V9: SAC '21 | Z9: Association for Computing Machinery | AA9: New York, NY, USA | AI9: event-place: Virtual Event, Republic of Korea | CL9: With the use of microservices, many software solutions have been improved in terms of scalability, response efficiency, ease of load balancing among others. However, it is still a challenge to dynamically deploy them according to devices' heterogeneity and energy consumption concerns, while maintaining a defined QoS. Centralized and decentralized approaches that manage microservices deployment have the traditional pros and cons long discussed over time. While the former offer greater control over distributed application components, the latter offers frugal network negotiations, no system-wide crashes, privacy, among others.This work focuses on identifying "ideal" host candidates for microservices' execution in a decentralized network, applying run-time scheduling operations (migration or duplication) to reduce energy consumption. To do this, we created a scheduling algorithm using MAAN (a P2P approach) to interpret a decentralized network as a multidimensional resource (capacity-demand) space, which supports range queries in a logarithmic quantity of hops. In this way, a node that runs a set of microservices is able to 1) map them in terms of their execution requirements (i.e. CPU frequency, RAM capacity, Network rate and disk speed) 2) Select an ideal microservice to be moved or duplicated, 3) find ideal node(s) that meet all those requirements in an optimal computational complexity and 4) negotiate the movement or duplication of the selected microservice, by analyzing energy consumption and QoS criteria. | DL9: cloud computing; microservices; power consumption; energy consumption; distributed algorithms; P2P
A10: 9PLCWDL9 | B10: conferencePaper | C10: 2023 | D10: Nam, T. B.; Khiem, H. G.; Triet, M. N.; Hong, K. V.; Khoa, T. D.; Bao, Q. T.; Phuc, N. T.; Hieu, M. D.; Loc, V. C. P.; Quy, T. L.; Anh, N. T.; Hien, Q. N.; Bang, L. K.; Trong, D. P. N.; Ngan, N. T. K.; Son, H.; Luong, H. H. | E10: SPaMeR: Securing Patient Medical Records in&nbsp;the&nbsp;Cloud - A Microservice and&nbsp;Brokerless Architecture Approach | F10: Web Services ‚Äì ICWS 2023: 30th International Conference, Held as Part of the Services Conference Federation, SCF 2023, Honolulu, HI, USA, September 23‚Äì26, 2023, Proceedings | G10: 978-3-031-44835-5 | I10: 10.1007/978-3-031-44836-2_3 | J10: https://doi.org/10.1007/978-3-031-44836-2_3 | K10: 2023 | L10: 45734.379 | M10: 45734.379 | O10: 32‚Äì46 | Z10: Springer-Verlag | AA10: Berlin, Heidelberg | AI10: event-place: Honolulu, HI, USA | CL10: The expansion of Internet of Things (IoT) technologies has revolutionized various sectors, one of the most critical being healthcare. The effective management of Patient Medical Records (PMRs) is an area where IoT plays a significant role, and its integration with Cloud Computing offers an enormous opportunity to enhance data accessibility, efficiency, and cost-effectiveness. However, the challenge of securing PMRs in the cloud remains a key concern. This paper introduces SPaMeR, an innovative IoT platform based on microservice and brokerless architecture, tailored to address this challenge and the specific requirements of healthcare environments. SPaMeR platform incorporates and extends the core functionalities of the IoT platform designed in our previous work - data collection, device and user management, and remote device control - while specifically addressing six critical issues for healthcare data: a) secure and reliable transmission of medical data, b) energy efficiency for healthcare devices, c) high-speed and accurate data collection from medical devices, d) robust security mechanisms to protect sensitive patient information, e) scalability to accommodate the ever-growing number of patients and medical devices, and f) compliance with healthcare data regulations and standards. To demonstrate the effectiveness and feasibility of SPaMeR, we provide a comprehensive evaluation with two distinct healthcare scenarios. Our results indicate significant improvements in the areas of data security, energy efficiency, and system scalability compared to traditional healthcare platforms. | DL10: microservice; micro-service; Internet of Things; Kafka; brokerless; gRPC; Medical record; RBAC; Single Sign-On
A11: VG2IIX98 | B11: conferencePaper | C11: 2024 | D11: D'Angelo, Andrea; d'Aloisio, Giordano | E11: Grammar-Based Anomaly Detection of Microservice Systems Execution Traces | F11: Companion of the 15th ACM/SPEC International Conference on Performance Engineering | G11: 979-8-4007-0445-1 | I11: 10.1145/3629527.3651844 | J11: https://doi.org/10.1145/3629527.3651844 | K11: 2024 | L11: 45734.379 | M11: 45734.379 | O11: 77‚Äì81 | V11: ICPE '24 Companion | Z11: Association for Computing Machinery | AA11: New York, NY, USA | AI11: event-place: London, United Kingdom | CL11: Microservice architectures are a widely adopted architectural pattern for large-scale applications. Given the large adoption of these systems, several works have been proposed to detect performance anomalies starting from analysing the execution traces. However, most of the proposed approaches rely on machine learning (ML) algorithms to detect anomalies. While ML methods may be effective in detecting anomalies, the training and deployment of these systems as been shown to be less efficient in terms of time, computational resources, and energy required.In this paper, we propose a novel approach based on Context-free grammar for anomaly detection of microservice systems execution traces. We employ the SAX encoding to transform execution traces into strings. Then, we select strings encoding anomalies, and for each possible anomaly, we build a Context-free grammar using the Sequitur grammar induction algorithm. We test our approach on two real-world datasets and compare it with a Logistic Regression classifier. We show how our approach is more effective in terms of training time of 15 seconds with a minimum loss in effectiveness of 5% compared to the Logistic Regression baseline. | DL11: anomaly detection; context-free grammar; execution traces; micro service system
A12: BL8MQIZ4 | B12: conferencePaper | C12: 2023 | D12: Attarha, Shadi; Forster, Anna | E12: Empowering IoT Applications with Flexible, Energy-Efficient Remote Management of Low-Power Edge Devices | F12: Proceedings of the 2023 International Conference on Embedded Wireless Systems and Networks | K12: 2023 | L12: 45734.379 | M12: 45734.379 | O12: 52‚Äì55 | V12: EWSN '23 | Z12: Association for Computing Machinery | AA12: New York, NY, USA | AI12: event-place: Rende, Italy | CL12: In the context of the Internet of Things (IoT), reliable and energy-efficient provision of IoT applications has become critical. Equipping IoT systems with tools that enable a flexible, well-performing, and automated way of monitoring and managing IoT edge devices is an essential prerequisite. In current IoT systems, low-power edge appliances have been utilized in a way that can not be controlled and re-configured in a timely manner. Hence, conducting a trade-off solution between manageability, performance and design requirements are demanded. This paper introduces a novel approach for fine-grained monitoring and managing individual micro-services within low-power edge devices, which improves system reliability and energy efficiency. The proposed method enables operational flexibility for IoT edge devices by leveraging a modularization technique. Following a review of existing solutions for remote-managed IoT services, a detailed description of the suggested approach is presented. Also, to explore the essential design principles that must be considered in this approach, the suggested architecture is elaborated in detail. Finally, the advantages of the proposed solution to deal with disruptions are demonstrated in the proof of concept-based experiments. | DL12: IoT; Energy Efficiency; Low-power; Operational Flexibility; Service Isolation; Service Management
A13: PCR376C8 | B13: conferencePaper | C13: 2024 | D13: Steidl, Monika; Leitner, Michael; Urbanke, Pirmin; Gattringer, Marko; Felderer, Michael; Ristov, Sashko | E13: Understanding Microservice Runtime Monitoring Data for&nbsp;Anomaly Detection with&nbsp;Structural Equation Modeling | F13: Product-Focused Software Process Improvement: 25th International Conference, PROFES 2024, Tartu, Estonia, December 2‚Äì4, 2024, Proceedings | G13: 978-3-031-78385-2 | I13: 10.1007/978-3-031-78386-9_31 | J13: https://doi.org/10.1007/978-3-031-78386-9_31 | K13: 2024 | L13: 45734.379 | M13: 45734.379 | O13: 404‚Äì413 | Z13: Springer-Verlag | AA13: Berlin, Heidelberg | AI13: event-place: Tartu, Estonia | CL13: Microservices reliability is critical, but runtime anomalies are increasingly common due to system complexity. Rule-based and AI-based anomaly detection methods assist practitioners in analyzing runtime monitoring data (logs, traces, metrics) to identify anomalies. However, these methods rely&nbsp;on high-quality datasets and deep domain knowledge to deliver accurate results. Thus, a significant challenge lies in the lack of consensus on which runtime monitoring parameters effectively represent&nbsp;the system and microservices, reliably indicate anomalies,&nbsp;or distinguish deviations that genuinely signal anomalies. A thorough understanding of the dataset, key monitoring parameters,&nbsp;and microservice dependencies is crucial to minimize bias and&nbsp;false positives, ultimately improving the effectiveness of anomaly detection methods.Thus, we investigate whether structural equation modeling&nbsp;can describe the system‚Äôs or microservices‚Äô behavior via indicators extracted from runtime monitoring data and identify their causal relationships. We used EvoMaster to simulate user behavior&nbsp;in TrainTicket and extract runtime monitoring data to test our model. Our results show that the identified indicators effectively describe microservices‚Äô behavior, but network indicators alone&nbsp;are insufficient for describing the whole system‚Äôs behavior. The&nbsp;model can also identify microservices that significantly influence&nbsp;the whole system‚Äôs behavior. | DL13: Metrics; Anomaly detection during runtime; Logs; Microservice; Monitoring data; PLS-SEM; Structural equation model; Traces
A14: 2PZIJ4MJ | B14: conferencePaper | C14: 2024 | D14: Mehran, Narges; Kimovski, Dragi; Hellwagner, Hermann; Roman, Dumitru; Soylu, Ahmet; Prodan, Radu | E14: Scheduling of Distributed Applications on the Computing Continuum: A Survey | F14: Proceedings of the IEEE/ACM 16th International Conference on Utility and Cloud Computing | G14: 979-8-4007-0234-1 | I14: 10.1145/3603166.3632540 | J14: https://doi.org/10.1145/3603166.3632540 | K14: 2024 | L14: 45734.379 | M14: 45734.379 | V14: UCC '23 | Z14: Association for Computing Machinery | AA14: New York, NY, USA | AI14: event-place: Taormina (Messina), Italy | CL14: The demand for distributed applications has significantly increased over the past decade, with improvements in machine learning techniques fueling this growth. These applications predominantly utilize Cloud data centers for high-performance computing and Fog and Edge devices for low-latency communication for small-size machine learning model training and inference. The challenge of executing applications with different requirements on heterogeneous devices requires effective methods for solving NP-hard resource allocation and application scheduling problems. The state-of-the-art techniques primarily investigate conflicting objectives, such as the completion time, energy consumption, and economic cost of application execution on the Cloud, Fog, and Edge computing infrastructure. Therefore, in this work, we review these research works considering their objectives, methods, and evaluation tools. Based on the review, we provide a discussion on the scheduling methods in the Computing Continuum. | DL14: energy efficiency; cloud; computing continuum; edge; placement; scheduling
A15: UVN6593I | B15: conferencePaper | C15: 2024 | D15: Vahabi, Shahrokh; Righetti, Francesca; Vallati, Carlo; Tonellotto, Nicola | E15: Energy-Efficient Resource Management for Real-Time Applications in FaaS Edge Computing Platforms | F15: Proceedings of the IEEE/ACM 16th International Conference on Utility and Cloud Computing | G15: 979-8-4007-0234-1 | I15: 10.1145/3603166.3632240 | J15: https://doi.org/10.1145/3603166.3632240 | K15: 2024 | L15: 45734.379 | M15: 45734.379 | V15: UCC '23 | Z15: Association for Computing Machinery | AA15: New York, NY, USA | AI15: event-place: Taormina (Messina), Italy | CL15: Edge computing and Function-as-a-Service are two emerging paradigms that enable a timed analysis of data directly in the proximity of cyber-physical systems and users. Function-as-a-service platforms deployed at the edge require mechanisms for resource management and allocation to schedule function execution and to scale the available resources in order to ensure the proper quality of service to applications. Large-scale deployments will also require mechanisms to control the energy consumption of the overall system, to ensure long-term sustainability. In this paper, we propose a technique to schedule function invocations on Edge resources by powering down idle edge nodes during period of low demands. In doing so, our technique aims at reducing the overall energy consumption without incurring in service level agreements violations. Experimental evaluations demonstrate that the proposed approach reduces service level agreement violations by at least 78.1% and energy consumption by at least 62.5% on average using synthetic and real-world datasets w.r.t. different baselines. | DL15: energy efficiency; resource management; edge computing; function-as-a-service; service level agreement
A16: 8IY924WC | B16: conferencePaper | C16: 2023 | D16: Dinga, Madalina; Malavolta, Ivano; Giamattei, Luca; Guerriero, Antonio; Pietrantuono, Roberto | E16: An Empirical Evaluation of&nbsp;the&nbsp;Energy and&nbsp;Performance Overhead of&nbsp;Monitoring Tools on&nbsp;Docker-Based Systems | F16: Service-Oriented Computing: 21st International Conference, ICSOC 2023, Rome, Italy, November 28 ‚Äì December 1, 2023, Proceedings, Part I | G16: 978-3-031-48420-9 | I16: 10.1007/978-3-031-48421-6_13 | J16: https://doi.org/10.1007/978-3-031-48421-6_13 | K16: 2023 | L16: 45734.379 | M16: 45734.379 | O16: 181‚Äì196 | Z16: Springer-Verlag | AA16: Berlin, Heidelberg | AI16: event-place: Rome, Italy | CL16: Context. Energy efficiency is gaining importance in the design of software systems, but is still marginally addressed in the area of microservice-based systems. Energy-related aspects often get neglected in favor of other software quality attributes, such as performance, service composition, maintainability, and security.Goal. The aim of this study is to identify, synthesize and empirically evaluate the energy and performance overhead of monitoring tools employed in the microservices and DevOps context.Method. We selected four representative monitoring tools in the microservices and DevOps context. These were evaluated via a controlled experiment on an open-source Docker-based microservice benchmark system.Results. The results highlight: i) the specific frequency and workload conditions under which energy consumption and performance metrics are impacted by the tools; ii) the differences between the tools; iii) the relation between energy and performance overhead.
A17: 64HBXE4Z | B17: conferencePaper | C17: 2023 | D17: Khairy, Mahmoud; Alawneh, Ahmad; Barnes, Aaron; Rogers, Timothy G. | E17: SIMR: Single Instruction Multiple Request Processing for Energy-Efficient Data Center Microservices | F17: Proceedings of the 55th Annual IEEE/ACM International Symposium on Microarchitecture | G17: 978-1-6654-6272-3 | I17: 10.1109/MICRO56248.2022.00040 | J17: https://doi.org/10.1109/MICRO56248.2022.00040 | K17: 2023 | L17: 45734.379 | M17: 45734.379 | O17: 441‚Äì463 | V17: MICRO '22 | Z17: IEEE Press | AA17: Chicago, Illinois, USA | CL17: Contemporary data center servers process thousands of similar, independent requests per minute. In the interest of programmer productivity and ease of scaling, workloads in data centers have shifted from single monolithic processes toward a micro and nanoservice software architecture. As a result, single servers are now packed with many threads executing the same, relatively small task on different data.State-of-the-art data centers run these microservices on multi-core CPUs. However, the flexibility offered by traditional CPUs comes at an energy-efficiency cost. The Multiple Instruction Multiple Data execution model misses opportunities to aggregate the similarity in contemporary microservices. We observe that the Single Instruction Multiple Thread execution model, employed by GPUs, provides better thread scaling and has the potential to reduce frontend and memory system energy consumption. However, contemporary GPUs are ill-suited for the latency-sensitive microservice space.To exploit the similarity in contemporary microservices, while maintaining acceptable latency, we propose the Request Processing Unit (RPU). The RPU combines elements of out-of-order CPUs with lockstep thread aggregation mechanisms found in GPUs to execute microservices in a Single Instruction Multiple Request (SIMR) fashion. To complement the RPU, we also propose a SIMR-aware software stack that uses novel mechanisms to batch requests based on their predicted control-flow, split batches based on predicted latency divergence and map per-request memory allocations to maximize coalescing opportunities. Our resulting RPU system processes 5.7√ó more requests/joule than multi-core CPUs, while increasing single thread latency by only 1.44√ó. | DL17: data center; GPU; microservices; SIMT
A18: 3QBSZ9JC | B18: conferencePaper | C18: 2023 | D18: Thiede, John; Bashir, Noman; Irwin, David; Shenoy, Prashant | E18: Carbon Containers: A System-level Facility for Managing Application-level Carbon Emissions | F18: Proceedings of the 2023 ACM Symposium on Cloud Computing | G18: 979-8-4007-0387-4 | I18: 10.1145/3620678.3624644 | J18: https://doi.org/10.1145/3620678.3624644 | K18: 2023 | L18: 45734.379 | M18: 45734.379 | O18: 17‚Äì31 | V18: SoCC '23 | Z18: Association for Computing Machinery | AA18: New York, NY, USA | AI18: event-place: Santa Cruz, CA, USA | CL18: To reduce their environmental impact, cloud datacenters' are increasingly focused on optimizing applications' carbon-efficiency, or work done per mass of carbon emitted. To facilitate such optimizations, we present Carbon Containers, a simple system-level facility, which extends prior work on power containers, that automatically regulates applications' carbon emissions in response to variations in both their work-load's intensity and their energy's carbon-intensity. Specifically, Carbon Containers enable applications to specify a maximum carbon emissions rate (in g.CO2e/hr), and then transparently enforce this rate via a combination of vertical scaling, container migration, and suspend/resume while maximizing either energy-efficiency or performance.Carbon Containers are especially useful for applications that i) must continue running even during high-carbon periods, and ii) execute in regions with few variations in carbon-intensity. These low-variability regions also tend to have high average carbon-intensity, which increases the importance of regulating carbon emissions. We implement a Carbon Container prototype by extending Linux Containers to incorporate the mechanisms above and evaluate it using real workload traces and carbon-intensity data from multiple regions. We compare Carbon Containers with prior work that regulates carbon emissions by suspending/resuming applications during high/low carbon periods. We show that Carbon Containers are more carbon-efficient and improve performance while maintaining similar carbon emissions. | DL18: Carbon-efficiency; energy-efficiency; performance
